<?xml version="1.0"?>
<robot name="mobile" xmlns:xacro="http://ros.org/wiki/xacro">
	<material name="blue">
		<color rgba="0 0 1.0 1.0"/>
	</material>
	<material name="black">
		<color rgba="0.1 0.1 0.1 1.0"/>
	</material>
	<material name="gray">
		<color rgba="0.3 0.3 0.3 1.0"/>
	</material>
	
	<xacro:macro name="wheel">
		<geometry>
			<mesh filename="package://mobile/car_parts/rviz/wheel.stl" scale="0.001 0.001 0.001"/>
		</geometry>
	</xacro:macro>

	<link name="base_link">
		<visual>
			<origin rpy="0 0 -1.5708" xyz="0.145 0.1375 0.048"/>
			<geometry>
				<mesh filename="package://mobile/car_parts/rviz/car-body.stl" scale="0.001 0.001 0.001"/>
			</geometry>
			<material name="blue"/>
		</visual>
		<collision>
			<origin rpy="0 0 -1.5708" xyz="0.145 0.1375 0.048"/>
			<geometry>
				<mesh filename="package://mobile/car_parts/rviz/car-body.stl" scale="0.001 0.001 0.001"/>
			</geometry>
		</collision>
	</link>

	<joint name="base_to_laser" type="fixed">
		<origin xyz="0.123 0 0"/>
		<parent link="base_link"/>
		<child link="laser"/>
	</joint>
	<link name="laser">
	</link>

	<joint name="base_to_camera" type="fixed">
		<origin xyz="0.41 0 0.12"/>
		<parent link="base_link"/>
		<child link="camera"/>
	</joint>
	<link name="camera">
		<visual>
			<origin rpy="1.5708 0 1.5708"/>
			<geometry>
				<mesh filename="package://mobile/car_parts/rviz/cam-f100.stl" scale="0.001 0.001 0.001"/>
			</geometry>
			<material name="black"/>
		</visual>
		<collision>
			<origin rpy="1.5708 0 1.5708"/>
			<geometry>
				<mesh filename="package://mobile/car_parts/rviz/cam-f100.stl" scale="0.001 0.001 0.001"/>
			</geometry>
		</collision>
	</link>

	<joint name="base_to_imu" type="fixed">
		<origin rpy="0 0 0" xyz="0.307 0 0.12"/>
		<parent link="base_link"/>
		<child link="imu_link"/>
	</joint>
	<link name="imu_link">
	</link>
	
	<joint name="front_steer_joint" type="revolute">
		<limit effort="100" lower="-1" upper="1" velocity="10"/>
		<axis xyz="0 0 -1"/>
		<origin xyz="0.326 0 0.052"/>
		<parent link="base_link"/>
		<child link="front_steer"/>
	</joint>	
	<link name="front_steer">
	</link>

	<joint name="front_left_wheel_revolute_joint" type="revolute">
		<limit effort="100" lower="-1" upper="1" velocity="10"/>		
		<axis xyz="0 0 1"/>
		<origin rpy="0 0 0" xyz="0.326 0.115 0.052"/>
		<mimic joint="front_steer_joint" multiplier="1.0"/>
		<parent link="base_link"/>
		<child link="front_left_wheel_revolute"/>	
	</joint>
	<link name="front_left_wheel_revolute">
	</link>
	

	<joint name="base_to_top_left_wheel" type="continuous">
		<origin rpy="0 0 0"/>
		<axis xyz="0 1 0"/>
		<mimic joint="base_to_bottom_left_wheel" multiplier="1.0"/>
		<parent link="front_left_wheel_revolute"/>
		<child link="top_left_wheel"/>
	</joint>
	<link name="top_left_wheel">
		<visual>
			<origin rpy="-1.5708 0 0"/>
			<xacro:wheel/>
			<material name="gray"/>
		</visual>
		<collision>
			<origin rpy="-1.5708 0 0"/>
			<xacro:wheel/>
		</collision>
	</link>

	<joint name="front_right_wheel_revolute_joint" type="revolute">
		<limit effort="100" lower="-1" upper="1" velocity="10"/>		
		<axis xyz="0 0 1"/>
		<origin rpy="0 0 0" xyz="0.326 -0.115 0.052"/>
		<mimic joint="front_steer_joint" multiplier="1.0"/>
		<parent link="base_link"/>
		<child link="front_right_wheel_revolute"/>	
	</joint>
	<link name="front_right_wheel_revolute">
	</link>

	<joint name="base_to_top_right_wheel" type="continuous">
		<origin rpy="0 0 0"/>
		<axis xyz="0 1 0"/>
		<mimic joint="base_to_bottom_right_wheel" multiplier="1.0"/>
		<parent link="front_right_wheel_revolute"/>
		<child link="top_right_wheel"/>
	</joint>
	<link name="top_right_wheel">
		<visual>
			<origin rpy="1.5708 3.14 0"/>
			<xacro:wheel/>
			<material name="gray"/>
		</visual>
		<collision>
			<origin rpy="1.5708 3.14 0"/>
			<xacro:wheel/>
		</collision>
	</link>

	<joint name="rear_wheel_joint" type="continuous">
		<axis xyz="0 1 0"/>
		<origin rpy="0 0 0" xyz="0 0 0.052"/>
		<parent link="base_link"/>
		<child link="rear_steer"/>
	</joint>	
	<link name="rear_steer">
	</link>

	<joint name="base_to_bottom_left_wheel" type="continuous">
		<axis xyz="0 0 1"/>
		<origin rpy="-1.5708 0 0" xyz="0 0.115 0.052"/>
		<mimic joint="rear_wheel_joint" multiplier="1.0"/>
		<parent link="base_link"/>
		<child link="bottom_left_wheel"/>
	</joint>
	<link name="bottom_left_wheel">
		<visual>
			<xacro:wheel/>
			<material name="gray"/>
		</visual>
		<collision>
			<xacro:wheel/>
		</collision>
	</link>

	<joint name="base_to_bottom_right_wheel" type="continuous">
		<axis xyz="0 0 -1"/>
		<origin rpy="1.5708 3.14 0" xyz="0 -0.115 0.052"/>
		<mimic joint="rear_wheel_joint" multiplier="1.0"/>
		<parent link="base_link"/>
		<child link="bottom_right_wheel"/>
	</joint>
	<link name="bottom_right_wheel">
		<visual>
			<xacro:wheel/>
			<material name="gray"/>
		</visual>
		<collision>
			<xacro:wheel/>
		</collision>
	</link>
</robot>
